Workbook

Sheet 封面
A1: 项目 | B1: 内容 | C1: 辅助项目 | D1: 辅助内容
A2: 公司 | B2: 上海云棱智能科技有限公司 | C2: 报告期间 | D2: 2025年Q1-Q4
A3: 报告名称 | B3: 上海云棱智能科技有限公司 财报与经营分析 | C3: 报告模板 | D3: 老板审阅 + 可追溯公式版
A4: 数据口径 | B4: 利润表/现金流量表按单季与累计拆分，资产负债表按期末余额；报告层统一换算为万元。 | C4: 金额单位 | D4: 人民币万元
A5: 核心结论 | B5: 全年营收 550.00 万元、净利润 98.52 万元，净利率 17.91%，收入与利润同步上行。 | C5: 现金质量 | D5: 经营现金流累计 110.50 万元，OCF/净利润（累计）112.16%，现金质量总体较好。
A6: 报告用途 | B6: 老板审阅 / 财务经营复盘 | C6: 生成日期 | D6: 46191
A7: 限制事项 | B7: 经营明细、预算、同行对标未提供；经营分析仅能基于三表做代理判断。 | C7: 数据性质 | D7: FIN_STMT（真实财务报表）；经营观察含有限推断

Sheet 老板摘要
A1: 模块 | B1: 管理层结论（事实+数字） | C1: 决策提示（管理含义）
A2: 总体表现 | B2: 全年营收 550.00 万元、净利润 98.52 万元，净利率 17.91%，收入与利润同步上行。 | C2: 全年收入、利润、现金均为正增长，主营扩张与盈利兑现同步。
A3: 增长质量 | B3: Q4 单季收入 178.00 万元，较 Q3 的 151.00 万元环比提升 17.88%。 | C3: 增速虽较 Q2/Q3 略放缓，但单季盈利率继续上行，增长质量仍偏健康。
A4: 现金质量 | B4: 经营现金流累计 110.50 万元，OCF/净利润（累计）112.16%，现金质量总体较好。 | C4: 经营现金流持续高于净利润，利润兑现为现金的能力较好。
A5: 偿债结构 | B5: 资产负债率由 Q1 的 46.39% 降至 Q4 的 40.90%，期末货币资金充足。 | C5: 杠杆水平改善，短中期偿债压力可控。
A6: 管理动作 | B6: 经营数据尚未覆盖客户、产品、合同、预算与回款账龄。 | C6: 下一步优先补经营明细，验证收入增长、费用投放和回款效率的驱动关系。

Sheet 经营概览
A1: 项目 | B1: 本次观察（数据事实） | C1: 管理说明（业务含义）
A2: 财务表现 | B2: 全年营收 550.00 万元、净利润 98.52 万元，净利率 17.91%，收入与利润同步上行。 | C2: 全年营收与净利润同增，财务主线明确。
A3: 收入趋势 | B3: 单季收入由 Q1 98.00 万元增至 Q4 178.00 万元。 | C3: 季度规模持续抬升，说明订单或交付节奏整体向上。
A4: 盈利趋势 | B4: Q4 单季净利率 20.92%，全年净利率 17.91%。 | C4: 利润率逐季改善，费用扩张未吞噬利润增长。
A5: 现金状态 | B5: Q4 单季 OCF/净利润 102.85%，全年累计为 112.16%。 | C5: 现金创造能力强于会计利润，利润质量较好。
A6: 费用效率 | B6: 全年销售/管理/研发费用分别为 69.70 / 144.70 / 91.50 万元。 | C6: 管理费用占比仍高，研发投入占比较高，后续要验证费用投入产出。
A7: 经营数据说明 | B7: 当前仅有三表，未提供预算、同行、客户、产品、订单、回款账龄等经营明细。 | C7: 经营分析结论属于财务代理判断，不替代业务侧明细诊断。

Sheet 利润分析
A1: 指标 | B1: 一季度 | C1: 二季度 | D1: 三季度 | E1: 四季度 | F1: 全年 | G1: 分析口径
A2: 营业收入 | B2: =ROUND(('利润表-2025Q1'!D4)/10000,2) -> 98 | C2: =ROUND(('利润表-2025Q2'!D4)/10000,2) -> 123 | D2: =ROUND(('利润表-2025Q3'!D4)/10000,2) -> 151 | E2: =ROUND(('利润表-2025Q4'!D4)/10000,2) -> 178 | F2: =ROUND(SUM(B2:E2),2) -> 550 | G2: 单季收入，来源于利润表本期金额；全年为 Q1-Q4 求和。
A3: 营业成本 | B3: =ROUND(('利润表-2025Q1'!D5)/10000,2) -> 22 | C3: =ROUND(('利润表-2025Q2'!D5)/10000,2) -> 27.5 | D3: =ROUND(('利润表-2025Q3'!D5)/10000,2) -> 35.6 | E3: =ROUND(('利润表-2025Q4'!D5)/10000,2) -> 43.2 | F3: =ROUND(SUM(B3:E3),2) -> 128.3 | G3: 单季成本，来源于利润表本期金额；全年为 Q1-Q4 求和。
A4: 毛利 | B4: =ROUND(B2-B3,2) -> 76 | C4: =ROUND(C2-C3,2) -> 95.5 | D4: =ROUND(D2-D3,2) -> 115.4 | E4: =ROUND(E2-E3,2) -> 134.8 | F4: =ROUND(SUM(B4:E4),2) -> 421.7 | G4: 营业收入 - 营业成本。
A5: 毛利率 | B5: =IFERROR(B4/B2,0) -> 0.7755102 | C5: =IFERROR(C4/C2,0) -> 0.77642276 | D5: =IFERROR(D4/D2,0) -> 0.76423841 | E5: =IFERROR(E4/E2,0) -> 0.75730337 | F5: =IFERROR(F4/F2,0) -> 0.76672727 | G5: 毛利 / 营业收入。
A6: 销售费用 | B6: =ROUND(('利润表-2025Q1'!D14)/10000,2) -> 12.5 | C6: =ROUND(('利润表-2025Q2'!D14)/10000,2) -> 15.8 | D6: =ROUND(('利润表-2025Q3'!D14)/10000,2) -> 18.8 | E6: =ROUND(('利润表-2025Q4'!D14)/10000,2) -> 22.6 | F6: =ROUND(SUM(B6:E6),2) -> 69.7 | G6: 单季销售费用；全年求和。
A7: 研发费用 | B7: =ROUND(('利润表-2025Q1'!D20)/10000,2) -> 18 | C7: =ROUND(('利润表-2025Q2'!D20)/10000,2) -> 21.5 | D7: =ROUND(('利润表-2025Q3'!D20)/10000,2) -> 24.5 | E7: =ROUND(('利润表-2025Q4'!D20)/10000,2) -> 27.5 | F7: =ROUND(SUM(B7:E7),2) -> 91.5 | G7: 单季研发费用；全年求和。
A8: 管理费用 | B8: =ROUND(('利润表-2025Q1'!D17)/10000,2) -> 31 | C8: =ROUND(('利润表-2025Q2'!D17)/10000,2) -> 34.5 | D8: =ROUND(('利润表-2025Q3'!D17)/10000,2) -> 38.2 | E8: =ROUND(('利润表-2025Q4'!D17)/10000,2) -> 41 | F8: =ROUND(SUM(B8:E8),2) -> 144.7 | G8: 单季管理费用；全年求和。
A9: 财务费用 | B9: =ROUND(('利润表-2025Q1'!D21)/10000,2) -> 0.36 | C9: =ROUND(('利润表-2025Q2'!D21)/10000,2) -> 0.42 | D9: =ROUND(('利润表-2025Q3'!D21)/10000,2) -> 0.51 | E9: =ROUND(('利润表-2025Q4'!D21)/10000,2) -> 0.64 | F9: =ROUND(SUM(B9:E9),2) -> 1.93 | G9: 单季财务费用；全年求和。
A10: 营业利润 | B10: =ROUND(('利润表-2025Q1'!D24)/10000,2) -> 13.72 | C10: =ROUND(('利润表-2025Q2'!D24)/10000,2) -> 22.75 | D10: =ROUND(('利润表-2025Q3'!D24)/10000,2) -> 32.73 | E10: =ROUND(('利润表-2025Q4'!D24)/10000,2) -> 42.31 | F10: =ROUND(SUM(B10:E10),2) -> 111.51 | G10: 单季营业利润；全年求和。
A11: 净利润 | B11: =ROUND(('利润表-2025Q1'!D35)/10000,2) -> 12.68 | C11: =ROUND(('利润表-2025Q2'!D35)/10000,2) -> 20.02 | D11: =ROUND(('利润表-2025Q3'!D35)/10000,2) -> 28.59 | E11: =ROUND(('利润表-2025Q4'!D35)/10000,2) -> 37.24 | F11: =ROUND(SUM(B11:E11),2) -> 98.53 | G11: 单季净利润；全年求和。
A12: 净利率 | B12: =IFERROR(B11/B2,0) -> 0.12938776 | C12: =IFERROR(C11/C2,0) -> 0.16276423 | D12: =IFERROR(D11/D2,0) -> 0.18933775 | E12: =IFERROR(E11/E2,0) -> 0.20921348 | F12: =IFERROR(F11/F2,0) -> 0.17914545 | G12: 净利润 / 营业收入。

Sheet 资产负债分析
A1: 一季度末 | B1: 二季度末 | C1: 三季度末 | D1: 四季度末 | E1: 指标 | F1: 管理观察
A2: =ROUND(('资产负债表-2025Q1'!C4)/10000,2) -> 79.5 | B2: =ROUND(('资产负债表-2025Q2'!C4)/10000,2) -> 91.6 | C2: =ROUND(('资产负债表-2025Q3'!C4)/10000,2) -> 111.1 | D2: =ROUND(('资产负债表-2025Q4'!C4)/10000,2) -> 133.9 | E2: 货币资金 | F2: 期末现金储备持续上升。
A3: =ROUND(('资产负债表-2025Q1'!C10)/10000,2) -> 33 | B3: =ROUND(('资产负债表-2025Q2'!C10)/10000,2) -> 39 | C3: =ROUND(('资产负债表-2025Q3'!C10)/10000,2) -> 45.5 | D3: =ROUND(('资产负债表-2025Q4'!C10)/10000,2) -> 51 | E3: 应收账款 | F3: 规模同步扩大，需要持续跟踪账龄和回款速度。
A4: =ROUND(('资产负债表-2025Q1'!C31)/10000,2) -> 130.7 | B4: =ROUND(('资产负债表-2025Q2'!C31)/10000,2) -> 149.8 | C4: =ROUND(('资产负债表-2025Q3'!C31)/10000,2) -> 177.2 | D4: =ROUND(('资产负债表-2025Q4'!C31)/10000,2) -> 207 | E4: 流动资产合计 | F4: 流动资产规模扩张，为增长提供周转基础。
A5: =ROUND(('资产负债表-2025Q1'!C55)/10000,2) -> 216.2 | B5: =ROUND(('资产负债表-2025Q2'!C55)/10000,2) -> 242.5 | C5: =ROUND(('资产负债表-2025Q3'!C55)/10000,2) -> 278.9 | D5: =ROUND(('资产负债表-2025Q4'!C55)/10000,2) -> 319.8 | E5: 资产总计 | F5: 总资产逐季抬升。
A6: =ROUND(('资产负债表-2025Q1'!C9)/10000,2) -> 21 | B6: =ROUND(('资产负债表-2025Q2'!C9)/10000,2) -> 24.5 | C6: =ROUND(('资产负债表-2025Q3'!C9)/10000,2) -> 28 | D6: =ROUND(('资产负债表-2025Q4'!C9)/10000,2) -> 31 | E6: 应付账款 | F6: 与业务规模扩张同步增长。
A7: =ROUND(('资产负债表-2025Q1'!C25)/10000,2) -> 57.5 | B7: =ROUND(('资产负债表-2025Q2'!C25)/10000,2) -> 68 | C7: =ROUND(('资产负债表-2025Q3'!C25)/10000,2) -> 79 | D7: =ROUND(('资产负债表-2025Q4'!C25)/10000,2) -> 88.8 | E7: 流动负债合计 | F7: 需结合回款节奏看短债压力。
A8: =ROUND(('资产负债表-2025Q1'!C37)/10000,2) -> 100.3 | B8: =ROUND(('资产负债表-2025Q2'!C37)/10000,2) -> 110.5 | C8: =ROUND(('资产负债表-2025Q3'!C37)/10000,2) -> 121.2 | D8: =ROUND(('资产负债表-2025Q4'!C37)/10000,2) -> 130.8 | E8: 负债合计 | F8: 整体负债绝对额上升但占比下降。
A9: =ROUND(('资产负债表-2025Q1'!C54)/10000,2) -> 115.9 | B9: =ROUND(('资产负债表-2025Q2'!C54)/10000,2) -> 132 | C9: =ROUND(('资产负债表-2025Q3'!C54)/10000,2) -> 157.7 | D9: =ROUND(('资产负债表-2025Q4'!C54)/10000,2) -> 189 | E9: 所有者权益合计 | F9: 利润留存推动权益持续增厚。
A10: =IFERROR(A8/A5,0) -> 0.46392229 | B10: =IFERROR(B8/B5,0) -> 0.4556701 | C10: =IFERROR(C8/C5,0) -> 0.43456436 | D10: =IFERROR(D8/D5,0) -> 0.40900563 | E10: 资产负债率 | F10: 杠杆水平逐季改善。

Sheet 现金流分析
A1: 指标 | B1: Q1 | C1: Q2 | D1: Q3 | E1: Q4 | F1: 全年/期末 | G1: 管理观察
A2: 经营现金流 | B2: =ROUND(('现金流量表-2025Q1'!C10)/10000,2) -> 18 | C2: =ROUND(('现金流量表-2025Q2'!C10)/10000,2) -> 22.2 | D2: =ROUND(('现金流量表-2025Q3'!C10)/10000,2) -> 32 | E2: =ROUND(('现金流量表-2025Q4'!C10)/10000,2) -> 38.3 | F2: =ROUND(SUM(B2:E2),2) -> 110.5 | G2: 单季经营现金流保持正值，全年累计高于净利润。
A3: 净利润 | B3: =利润分析!B11 -> 12.68 | C3: =利润分析!C11 -> 20.02 | D3: =利润分析!D11 -> 28.59 | E3: =利润分析!E11 -> 37.24 | F3: =利润分析!F11 -> 98.53 | G3: 与利润分析保持一致。
A4: OCF/净利润 | B4: =IFERROR(B2/B3,0) -> 1.4195584 | C4: =IFERROR(C2/C3,0) -> 1.1088911 | D4: =IFERROR(D2/D3,0) -> 1.1192725 | E4: =IFERROR(E2/E3,0) -> 1.028464 | F4: =IFERROR(F2/F3,0) -> 1.1214858 | G4: 观察利润兑现为现金的质量。
A5: 期末现金余额 | B5: =资产负债分析!A2 -> 79.5 | C5: =资产负债分析!B2 -> 91.6 | D5: =资产负债分析!C2 -> 111.1 | E5: =资产负债分析!D2 -> 133.9 | F5: =E5 -> 133.9 | G5: 来自资产负债表货币资金，并与现金流期末现金勾稽。

Sheet 关键指标
A1: 一季度 | B1: 二季度 | C1: 三季度 | D1: 四季度 | E1: 全年/期末 | F1: 指标
A2: =利润分析!B2 -> 98 | B2: =利润分析!C2 -> 123 | C2: =利润分析!D2 -> 151 | D2: =利润分析!E2 -> 178 | E2: =利润分析!F2 -> 550 | F2: 营业收入
A3: =利润分析!B4 -> 76 | B3: =利润分析!C4 -> 95.5 | C3: =利润分析!D4 -> 115.4 | D3: =利润分析!E4 -> 134.8 | E3: =利润分析!F4 -> 421.7 | F3: 毛利
A4: =利润分析!B5 -> 0.7755102 | B4: =利润分析!C5 -> 0.77642276 | C4: =利润分析!D5 -> 0.76423841 | D4: =利润分析!E5 -> 0.75730337 | E4: =利润分析!F5 -> 0.76672727 | F4: 毛利率
A5: =利润分析!B10 -> 13.72 | B5: =利润分析!C10 -> 22.75 | C5: =利润分析!D10 -> 32.73 | D5: =利润分析!E10 -> 42.31 | E5: =利润分析!F10 -> 111.51 | F5: 营业利润
A6: =利润分析!B11 -> 12.68 | B6: =利润分析!C11 -> 20.02 | C6: =利润分析!D11 -> 28.59 | D6: =利润分析!E11 -> 37.24 | E6: =利润分析!F11 -> 98.53 | F6: 净利润
A7: =利润分析!B12 -> 0.12938776 | B7: =利润分析!C12 -> 0.16276423 | C7: =利润分析!D12 -> 0.18933775 | D7: =利润分析!E12 -> 0.20921348 | E7: =利润分析!F12 -> 0.17914545 | F7: 净利率
A8: =现金流分析!B2 -> 18 | B8: =现金流分析!C2 -> 22.2 | C8: =现金流分析!D2 -> 32 | D8: =现金流分析!E2 -> 38.3 | E8: =现金流分析!F2 -> 110.5 | F8: 经营现金流
A9: =资产负债分析!A2 -> 79.5 | B9: =资产负债分析!B2 -> 91.6 | C9: =资产负债分析!C2 -> 111.1 | D9: =资产负债分析!D2 -> 133.9 | E9: =资产负债分析!D2 -> 133.9 | F9: 期末货币资金
A10: =资产负债分析!A5 -> 216.2 | B10: =资产负债分析!B5 -> 242.5 | C10: =资产负债分析!C5 -> 278.9 | D10: =资产负债分析!D5 -> 319.8 | E10: =资产负债分析!D5 -> 319.8 | F10: 资产总计
A11: =资产负债分析!A10 -> 0.46392229 | B11: =资产负债分析!B10 -> 0.4556701 | C11: =资产负债分析!C10 -> 0.43456436 | D11: =资产负债分析!D10 -> 0.40900563 | E11: =资产负债分析!D10 -> 0.40900563 | F11: 资产负债率

Sheet 风险与建议
A1: 类型 | B1: 事项 | C1: 判断 | D1: 建议
A2: 数据范围 | B2: 当前仅有三表，经营侧明细和预算未提供。 | C2: 经营分析深度受限。 | D2: 补充客户/产品/合同/预算/账龄后再做驱动拆解。
A3: 利润质量 | B3: 全年净利率 17.91%，Q4 单季净利率 20.92%。 | C3: 盈利能力改善。 | D3: 继续跟踪毛利率与费用率拐点，防止增长换利润。
A4: 现金质量 | B4: 全年 OCF/净利润 112.16%。 | C4: 现金质量较好。 | D4: 保持回款节奏，避免应收继续快于收入扩张。
A5: 偿债结构 | B5: 资产负债率由 46.39% 降至 40.90%。 | C5: 偿债结构改善。 | D5: 关注流动负债与货币资金的匹配及中长期资金安排。
A6: 管理跟进 | B6: Q4 期末应收账款 51.00 万元，较 Q1 的 33.00 万元明显上升。 | C6: 规模扩张伴随营运资金占用上升。 | D6: 建立回款和账龄跟踪台账，验证增长的现金含量。

Sheet 追问支持
A1: 可追问主题 | B1: 可追溯依据 | C1: 可下钻字段 | D1: 需要补充资料
A2: 收入与利润趋势 | B2: 利润表-2025Q1~Q4 本期金额 + 利润分析公式区 | C2: 分季度收入、成本、净利润 | D2: 订单、客户、产品、地区收入结构
A3: 费用结构 | B3: 利润表-2025Q1~Q4 销售/研发/管理/财务费用 | C3: 费用分季度、费用率 | D3: 费用明细台账、预算口径
A4: 资产和偿债能力 | B4: 资产负债表-2025Q1~Q4 资产总计/负债合计/权益 | C4: 债务结构、营运资金 | D4: 借款结构、账龄、供应商付款周期
A5: 现金流质量 | B5: 现金流量表-2025Q1~Q4 经营现金流、期末现金余额 | C5: 单季/累计 OCF、现金勾稽 | D5: 回款明细、收支预测
A6: 经营数据缺口 | B6: 封面/经营概览/限制事项 | C6: 预算、同行、业务明细 | D6: 预算、同行对标、经营 KPI 明细

Sheet 关键指标总览
A1: 指标 | B1: Q1 | C1: Q2 | D1: Q3 | E1: Q4 | F1: 全年/期末 | G1: 口径 / 说明
A2: 营业收入（万元，累计） | B2: =ROUND(('利润表-2025Q1'!C4)/10000,2) -> 98 | C2: =ROUND(('利润表-2025Q2'!C4)/10000,2) -> 221 | D2: =ROUND(('利润表-2025Q3'!C4)/10000,2) -> 372 | E2: =ROUND(('利润表-2025Q4'!C4)/10000,2) -> 550 | F2: =ROUND(('利润表-2025Q4'!C4)/10000,2) -> 550 | G2: 累计值；全年口径使用 Q4 本年累计
A3: 营业收入（单季，万元） | B3: =利润分析!B2 -> 98 | C3: =利润分析!C2 -> 123 | D3: =利润分析!D2 -> 151 | E3: =利润分析!E2 -> 178 | F3: =- | G3: 单季金额；用于环比和季度趋势
A4: 单季营收环比 | B4: =- | C4: =IFERROR(C3/B3-1,0) -> 0.25510204 | D4: =IFERROR(D3/C3-1,0) -> 0.22764228 | E4: =IFERROR(E3/D3-1,0) -> 0.17880795 | F4: =- | G4: 仅使用单季收入计算，不使用累计收入
A5: 毛利率（累计） | B5: =IFERROR(((ROUND(('利润表-2025Q1'!C4)/10000,2)-ROUND(('利润表-2025Q1'!C5)/10000,2)))/(ROUND(('利润表-2025Q1'!C4)/10000,2)),0) -> 0.7755102 | C5: =IFERROR(((ROUND(('利润表-2025Q2'!C4)/10000,2)-ROUND(('利润表-2025Q2'!C5)/10000,2)))/(ROUND(('利润表-2025Q2'!C4)/10000,2)),0) -> 0.7760181 | D5: =IFERROR(((ROUND(('利润表-2025Q3'!C4)/10000,2)-ROUND(('利润表-2025Q3'!C5)/10000,2)))/(ROUND(('利润表-2025Q3'!C4)/10000,2)),0) -> 0.77123656 | E5: =IFERROR(((ROUND(('利润表-2025Q4'!C4)/10000,2)-ROUND(('利润表-2025Q4'!C5)/10000,2)))/(ROUND(('利润表-2025Q4'!C4)/10000,2)),0) -> 0.76672727 | F5: =IFERROR(((ROUND(('利润表-2025Q4'!C4)/10000,2)-ROUND(('利润表-2025Q4'!C5)/10000,2)))/(ROUND(('利润表-2025Q4'!C4)/10000,2)),0) -> 0.76672727 | G5: 毛利 / 营收；累计口径
A6: 净利率（累计） | B6: =ROUND(('利润表-2025Q1'!C24)/10000,2) -> 13.72 | C6: =ROUND(('利润表-2025Q2'!C24)/10000,2) -> 36.47 | D6: =ROUND(('利润表-2025Q3'!C24)/10000,2) -> 69.2 | E6: =ROUND(('利润表-2025Q4'!C24)/10000,2) -> 111.51 | F6: =ROUND(('利润表-2025Q4'!C24)/10000,2) -> 111.51 | G6: 净利润 / 营收；累计口径
A7: 营业利润（万元，累计） | B7: =ROUND(('利润表-2025Q1'!C35)/10000,2) -> 12.68 | C7: =ROUND(('利润表-2025Q2'!C35)/10000,2) -> 32.7 | D7: =ROUND(('利润表-2025Q3'!C35)/10000,2) -> 61.29 | E7: =ROUND(('利润表-2025Q4'!C35)/10000,2) -> 98.52 | F7: =ROUND(('利润表-2025Q4'!C35)/10000,2) -> 98.52 | G7: 利润表本年累计金额
A8: 净利润（万元，累计） | B8: =IFERROR((ROUND(('利润表-2025Q1'!C35)/10000,2))/(ROUND(('利润表-2025Q1'!C4)/10000,2)),0) -> 0.12938776 | C8: =IFERROR((ROUND(('利润表-2025Q2'!C35)/10000,2))/(ROUND(('利润表-2025Q2'!C4)/10000,2)),0) -> 0.1479638 | D8: =IFERROR((ROUND(('利润表-2025Q3'!C35)/10000,2))/(ROUND(('利润表-2025Q3'!C4)/10000,2)),0) -> 0.16475806 | E8: =IFERROR((ROUND(('利润表-2025Q4'!C35)/10000,2))/(ROUND(('利润表-2025Q4'!C4)/10000,2)),0) -> 0.17912727 | F8: =IFERROR((ROUND(('利润表-2025Q4'!C35)/10000,2))/(ROUND(('利润表-2025Q4'!C4)/10000,2)),0) -> 0.17912727 | G8: 利润表本年累计金额
A9: 经营现金流（累计，万元） | B9: =ROUND(('现金流量表-2025Q1'!D10)/10000,2) -> 18 | C9: =ROUND(('现金流量表-2025Q2'!D10)/10000,2) -> 40.2 | D9: =ROUND(('现金流量表-2025Q3'!D10)/10000,2) -> 72.2 | E9: =ROUND(('现金流量表-2025Q4'!D10)/10000,2) -> 110.5 | F9: =ROUND(('现金流量表-2025Q4'!D10)/10000,2) -> 110.5 | G9: 现金流量表本年累计金额
A10: OCF / 净利润（单季） | B10: =现金流分析!B4 -> 1.4195584 | C10: =现金流分析!C4 -> 1.1088911 | D10: =现金流分析!D4 -> 1.1192725 | E10: =现金流分析!E4 -> 1.028464 | F10: =- | G10: 经营现金流单季 / 净利润单季
A11: OCF / 净利润（累计） | B11: =IFERROR(B9/B7,0) -> 1.4195584 | C11: =IFERROR(C9/C7,0) -> 1.2293578 | D11: =IFERROR(D9/D7,0) -> 1.1780062 | E11: =IFERROR(E9/E7,0) -> 1.1215997 | F11: =IFERROR(F9/F7,0) -> 1.1215997 | G11: 经营现金流累计 / 净利润累计
A12: 期末货币资金（万元） | B12: =资产负债分析!A2 -> 79.5 | C12: =资产负债分析!B2 -> 91.6 | D12: =资产负债分析!C2 -> 111.1 | E12: =资产负债分析!D2 -> 133.9 | F12: =资产负债分析!D2 -> 133.9 | G12: 资产负债表期末数；应与现金流期末现金勾稽
A13: 资产总计（万元） | B13: =资产负债分析!A5 -> 216.2 | C13: =资产负债分析!B5 -> 242.5 | D13: =资产负债分析!C5 -> 278.9 | E13: =资产负债分析!D5 -> 319.8 | F13: =资产负债分析!D5 -> 319.8 | G13: 资产负债表期末数
A14: 资产负债率（期末） | B14: =资产负债分析!A10 -> 0.46392229 | C14: =资产负债分析!B10 -> 0.4556701 | D14: =资产负债分析!C10 -> 0.43456436 | E14: =资产负债分析!D10 -> 0.40900563 | F14: =资产负债分析!D10 -> 0.40900563 | G14: 负债合计 / 资产总计
A15: 应收账款（万元，期末） | B15: =资产负债分析!A3 -> 33 | C15: =资产负债分析!B3 -> 39 | D15: =资产负债分析!C3 -> 45.5 | E15: =资产负债分析!D3 -> 51 | F15: =资产负债分析!D3 -> 51 | G15: 资产负债表期末数
A16: 研发费用（万元，累计） | B16: =ROUND(('利润表-2025Q1'!C20)/10000,2) -> 18 | C16: =ROUND(('利润表-2025Q2'!C20)/10000,2) -> 39.5 | D16: =ROUND(('利润表-2025Q3'!C20)/10000,2) -> 64 | E16: =ROUND(('利润表-2025Q4'!C20)/10000,2) -> 91.5 | F16: =ROUND(('利润表-2025Q4'!C20)/10000,2) -> 91.5 | G16: 利润表本年累计金额；研究费用映射为研发费用

Sheet 财务经营Dashboard
A1: 指标 | B1: Q1 | C1: Q2 | D1: Q3 | E1: Q4 | F1: 全年/期末 | G1: 口径 / 说明
A2: 营业收入（万元，累计） | B2: ='关键指标总览'!B2 -> 98 | C2: ='关键指标总览'!C2 -> 221 | D2: ='关键指标总览'!D2 -> 372 | E2: ='关键指标总览'!E2 -> 550 | F2: ='关键指标总览'!F2 -> 550 | G2: 累计值；全年口径使用 Q4 本年累计
A3: 营业收入（单季，万元） | B3: ='关键指标总览'!B3 -> 98 | C3: ='关键指标总览'!C3 -> 123 | D3: ='关键指标总览'!D3 -> 151 | E3: ='关键指标总览'!E3 -> 178 | F3: ='关键指标总览'!F3 | G3: 单季金额；用于环比和季度趋势
A4: 单季营收环比 | B4: ='关键指标总览'!B4 | C4: ='关键指标总览'!C4 -> 0.25510204 | D4: ='关键指标总览'!D4 -> 0.22764228 | E4: ='关键指标总览'!E4 -> 0.17880795 | F4: ='关键指标总览'!F4 | G4: 仅使用单季收入计算，不使用累计收入
A5: 毛利率（累计） | B5: ='关键指标总览'!B5 -> 0.7755102 | C5: ='关键指标总览'!C5 -> 0.7760181 | D5: ='关键指标总览'!D5 -> 0.77123656 | E5: ='关键指标总览'!E5 -> 0.76672727 | F5: ='关键指标总览'!F5 -> 0.76672727 | G5: 毛利 / 营收；累计口径
A6: 净利率（累计） | B6: ='关键指标总览'!B6 -> 13.72 | C6: ='关键指标总览'!C6 -> 36.47 | D6: ='关键指标总览'!D6 -> 69.2 | E6: ='关键指标总览'!E6 -> 111.51 | F6: ='关键指标总览'!F6 -> 111.51 | G6: 净利润 / 营收；累计口径
A7: 营业利润（万元，累计） | B7: ='关键指标总览'!B7 -> 12.68 | C7: ='关键指标总览'!C7 -> 32.7 | D7: ='关键指标总览'!D7 -> 61.29 | E7: ='关键指标总览'!E7 -> 98.52 | F7: ='关键指标总览'!F7 -> 98.52 | G7: 利润表本年累计金额
A8: 净利润（万元，累计） | B8: ='关键指标总览'!B8 -> 0.12938776 | C8: ='关键指标总览'!C8 -> 0.1479638 | D8: ='关键指标总览'!D8 -> 0.16475806 | E8: ='关键指标总览'!E8 -> 0.17912727 | F8: ='关键指标总览'!F8 -> 0.17912727 | G8: 利润表本年累计金额
A9: 经营现金流（累计，万元） | B9: ='关键指标总览'!B9 -> 18 | C9: ='关键指标总览'!C9 -> 40.2 | D9: ='关键指标总览'!D9 -> 72.2 | E9: ='关键指标总览'!E9 -> 110.5 | F9: ='关键指标总览'!F9 -> 110.5 | G9: 现金流量表本年累计金额
A10: OCF / 净利润（单季） | B10: ='关键指标总览'!B10 -> 1.4195584 | C10: ='关键指标总览'!C10 -> 1.1088911 | D10: ='关键指标总览'!D10 -> 1.1192725 | E10: ='关键指标总览'!E10 -> 1.028464 | F10: ='关键指标总览'!F10 | G10: 经营现金流单季 / 净利润单季
A11: OCF / 净利润（累计） | B11: ='关键指标总览'!B11 -> 1.4195584 | C11: ='关键指标总览'!C11 -> 1.2293578 | D11: ='关键指标总览'!D11 -> 1.1780062 | E11: ='关键指标总览'!E11 -> 1.1215997 | F11: ='关键指标总览'!F11 -> 1.1215997 | G11: 经营现金流累计 / 净利润累计
A12: 期末货币资金（万元） | B12: ='关键指标总览'!B12 -> 79.5 | C12: ='关键指标总览'!C12 -> 91.6 | D12: ='关键指标总览'!D12 -> 111.1 | E12: ='关键指标总览'!E12 -> 133.9 | F12: ='关键指标总览'!F12 -> 133.9 | G12: 资产负债表期末数；应与现金流期末现金勾稽
A13: 资产总计（万元） | B13: ='关键指标总览'!B13 -> 216.2 | C13: ='关键指标总览'!C13 -> 242.5 | D13: ='关键指标总览'!D13 -> 278.9 | E13: ='关键指标总览'!E13 -> 319.8 | F13: ='关键指标总览'!F13 -> 319.8 | G13: 资产负债表期末数
... A16: 研发费用（万元，累计） | B16: ='关键指标总览'!B16 -> 18 | C16: ='关键指标总览'!C16 -> 39.5 | D16: ='关键指标总览'!D16 -> 64 | E16: ='关键指标总览'!E16 -> 91.5 | F16: ='关键指标总览'!F16 -> 91.5 | G16: 利润表本年累计金额；研究费用映射为研发费用

Sheet 深度分析报告
A1: 模块 | B1: 数据事实 | C1: 管理判断 | D1: 建议动作
A2: 收入增长与规模扩张 | B2: 全年营收 550.00 万元，Q1→Q4 单季收入持续增长。 | C2: 公司 2025 年处于扩张周期，收入增长具有连续性。 | D2: 继续拆分客户、产品、交付节奏，验证增长来源是否均衡。
A3: 盈利能力与费用吸收 | B3: 全年毛利率 76.67%，全年净利率 17.91%。 | C3: 毛利率略有回落但净利率上行，说明费用吸收和规模效应在改善。 | D3: 重点盯管理费用与研发费用投入产出比。
A4: 现金质量与利润兑现 | B4: 全年经营现金流 110.50 万元，高于净利润 98.52 万元。 | C4: 现金流覆盖利润，利润质量较高。 | D4: 保持回款和支出纪律，防止扩张期现金消耗转弱。
A5: 资产结构与偿债能力 | B5: Q4 货币资金 133.90 万元，资产负债率 40.90%。 | C5: 账面流动性较稳，杠杆下降提升抗风险能力。 | D5: 补充借款结构和现金预测，确认中长期资金安排。
A6: 营运资金与回款压力 | B6: 应收账款从 Q1 的 33.00 万元增至 Q4 的 51.00 万元。 | C6: 收入扩张带来营运资金占用上升，后续要验证回款质量。 | D6: 补账龄、回款和坏账准备数据。
A7: 经营分析边界 | B7: 未提供客户、订单、产品、区域、预算、同行等经营明细。 | C7: 当前经营结论仅能依据三表做代理判断。 | D7: 补经营底稿后再做经营驱动分析与预算偏差分析。

Sheet 数据与计算审核报告
A1: 检查项 | B1: 结论 | C1: 说明
A2: 数据来源核验 | B2: PASS | C2: 共识别 12 份正式财务报表文件，覆盖 2025 年 Q1-Q4 的利润表、资产负债表、现金流量表。
A3: 公司一致性 | B3: PASS | C3: 解析公司名为 上海云棱智能科技有限公司，与任务对象一致。
A4: 金额单位统一 | B4: PASS | C4: 原始文件均为元，报告层统一换算为万元，比例指标保持小数口径。
A5: 三表勾稽：资产负债平衡 | B5: PASS | C5: Q1 资产总计与负债+权益差异 0.0 元。
A6: 三表勾稽：期末现金一致 | B6: PASS | C6: Q1 资产负债表货币资金与现金流量表期末现金差异 0.0 元。
A7: 三表勾稽：资产负债平衡 | B7: PASS | C7: Q2 资产总计与负债+权益差异 0.0 元。
A8: 三表勾稽：期末现金一致 | B8: PASS | C8: Q2 资产负债表货币资金与现金流量表期末现金差异 0.0 元。
A9: 三表勾稽：资产负债平衡 | B9: PASS | C9: Q3 资产总计与负债+权益差异 0.0 元。
A10: 三表勾稽：期末现金一致 | B10: PASS | C10: Q3 资产负债表货币资金与现金流量表期末现金差异 0.0 元。
A11: 三表勾稽：资产负债平衡 | B11: PASS | C11: Q4 资产总计与负债+权益差异 0.0 元。
A12: 三表勾稽：期末现金一致 | B12: PASS | C12: Q4 资产负债表货币资金与现金流量表期末现金差异 0.0 元。
... A14: 审核结论 | B14: PASS_WITH_WARNINGS | C14: 财务口径、勾稽关系和公式链条可交付；经营驱动分析需补数据后深化。

Sheet 关键数据溯源摘要
A1: 指标 | B1: 季度 | C1: 口径 | D1: 单位 | E1: 公式 | F1: 来源
A2: 营业收入 | B2: Q4 | C2: 单季 | D2: 万元 | E2: =利润分析!E2 -> 178 | F2: 利润表-2025Q4 / 一、营业收入 / 上海云棱智能科技有限公司-利润表-2025年Q4.xlsx / 利润表2025年第4季度 / A4:D4
A3: 营业收入 | B3: 全年 | C3: Q1-Q4 单季求和 | D3: 万元 | E3: =利润分析!F2 -> 550 | F3: 利润分析!B2:E2；来源于 Q1-Q4 利润表本期金额
A4: 净利润 | B4: Q4 | C4: 单季 | D4: 万元 | E4: =利润分析!E11 -> 37.24 | F4: 利润表-2025Q4 / 四、净利润 / 上海云棱智能科技有限公司-利润表-2025年Q4.xlsx / 利润表2025年第4季度 / A35:D35
A5: 净利润 | B5: 全年 | C5: Q1-Q4 单季求和 | D5: 万元 | E5: =利润分析!F11 -> 98.53 | F5: 利润分析!B11:E11；来源于 Q1-Q4 利润表本期金额
A6: 经营现金流 | B6: 全年 | C6: 累计 | D6: 万元 | E6: =关键指标总览!F8 -> 0.17912727 | F6: 现金流量表-2025Q4 / 经营活动产生的现金流量净额 / 上海云棱智能科技有限公司-现金流量表-2025年Q4.xlsx / 现金流量表2025年4季度 / A11:D11
A7: 期末货币资金 | B7: Q4 | C7: 期末 | D7: 万元 | E7: =资产负债分析!D2 -> 133.9 | F7: 资产负债表-2025Q4 / 货币资金 / 上海云棱智能科技有限公司-资产负债表-2025年Q4.xlsx / 资产负债表2025年12期 / A5:D5
A8: 资产总计 | B8: Q4 | C8: 期末 | D8: 万元 | E8: =资产负债分析!D5 -> 319.8 | F8: 资产负债表-2025Q4 / 资产总计 / 上海云棱智能科技有限公司-资产负债表-2025年Q4.xlsx / 资产负债表2025年12期 / A35:D35
A9: 资产负债率 | B9: Q4 | C9: 期末 | D9: % | E9: =资产负债分析!D10 -> 0.40900563 | F9: 资产负债分析!D8 / D5；上游来自 Q4 资产负债表负债合计与资产总计
A10: 研发费用 | B10: 全年 | C10: 累计 | D10: 万元 | E10: =关键指标总览!F15 -> 51 | F10: 利润表-2025Q4 / 研发费用 / 上海云棱智能科技有限公司-利润表-2025年Q4.xlsx / 利润表2025年第4季度 / A20:D20
A11: 应收账款 | B11: Q4 | C11: 期末 | D11: 万元 | E11: =关键指标总览!F14 -> 0.40900563 | F11: 资产负债表-2025Q4 / 应收账款 / 上海云棱智能科技有限公司-资产负债表-2025年Q4.xlsx / 资产负债表2025年12期 / A8:D8

Sheet 限制事项与下一步
A1: 事项 | B1: 说明
A2: 限制事项 | B2: 当前未提供预算、同行、客户、产品、订单、合同、回款账龄等经营数据，本次经营分析仅基于三表数据。
A3: 下一步 1 | B3: 补预算和目标值，新增预算偏差分析。
A4: 下一步 2 | B4: 补客户/产品/订单/账龄，新增经营驱动分析页。
A5: 下一步 3 | B5: 补同行或行业基准，新增对标分析与风险分层。

Sheet 利润表-2025Q1
A1: 利润表
A2: 编制单位：上海云棱智能科技有限公司 | B2: 2025年第1季度 | D2: 单位：元
A3: 项目 | B3: 行次 | C3: 本年累计金额 | D3: 本期金额
A4: 一、营业收入 | B4: 1 | C4: 980000 | D4: 980000
A5: 减：营业成本 | B5: 2 | C5: 220000 | D5: 220000
A6: 税金及附加 | B6: 3 | C6: 4200 | D6: 4200
A7: 其中：消费税 | B7: 4
A8: 营业税 | B8: 5
A9: 城市维护建设税 | B9: 6
A10: 资源税 | B10: 7
A11: 土地增值税 | B11: 8
A12: 城镇土地使用税、房产税、车船税、印花税 | B12: 9
A13: 教育费附加、矿产资源补偿税、排污费 | B13: 10
A14: 销售费用 | B14: 11 | C14: 125000 | D14: 125000
A15: 其中：商品维修费 | B15: 12
A16: 广告费和业务宣传费 | B16: 13 | C16: 68750 | D16: 68750
A17: 管理费用 | B17: 14 | C17: 310000 | D17: 310000
A18: 其中：开办费 | B18: 15
A19: 业务招待费 | B19: 16 | C19: 3720 | D19: 3720
A20: 研发费用 | B20: 17 | C20: 180000 | D20: 180000
A21: 财务费用 | B21: 18 | C21: 3600 | D21: 3600
A22: 其中：利息费用(收入以"-"号填列) | B22: 19 | C22: 3600 | D22: 3600
A23: 加：投资收益(损失以"-"号填列) | B23: 20
A24: 二、营业利润 | B24: 21 | C24: 137200 | D24: 137200
A25: 加：营业外收入 | B25: 22 | C25: 12000 | D25: 12000
A26: 其中：政府补助 | B26: 23
A27: 减：营业外支出 | B27: 24
A28: 其中：坏账损失 | B28: 25
A29: 无法收回的长期债券投资损失 | B29: 26
A30: 无法收回的长期股权投资损失 | B30: 27
A31: 自然灾害等不可抗力因素造成的损失 | B31: 28
A32: 税收滞纳金 | B32: 29
A33: 三、利润总额(亏损总额以"-"号填列) | B33: 30 | C33: 149200 | D33: 149200
A34: 减：所得税费用 | B34: 31 | C34: 22380 | D34: 22380
A35: 四、净利润 | B35: 32 | C35: 126820 | D35: 126820

Sheet 资产负债表-2025Q1
A1: 资产负债表
A2: 编制单位：上海云棱智能科技有限公司 | B2: 45747 | D2: 单位：元
A3: 项目 | B3: 行次 | C3: 期末余额 | D3: 年初余额
A4: 货币资金 | B4: 1 | C4: 795000 | D4: 450000
A5: 短期借款 | B5: 31
A6: 短期投资 | B6: 2
A7: 应付票据 | B7: 32
A8: 应收票据 | B8: 3
A9: 应付账款 | B9: 33 | C9: 210000 | D9: 180000
A10: 应收账款 | B10: 4 | C10: 330000 | D10: 260000
A11: 预收账款 | B11: 34 | C11: 110000 | D11: 90000
A12: 预付账款 | B12: 5 | C12: 90000 | D12: 80000
A13: 应付职工薪酬 | B13: 35 | C13: 138000 | D13: 125000
A14: 应收股利 | B14: 6
A15: 应交税费 | B15: 36 | C15: 41000 | D15: 35000
A16: 应收利息 | B16: 7
A17: 应付利息 | B17: 37
A18: 其他应收款 | B18: 8 | C18: 50000 | D18: 45000
A19: 应付利润 | B19: 38
A20: 存货 | B20: 9
A21: 其他应付款 | B21: 39 | C21: 76000 | D21: 70000
A22: 其中：原材料 | B22: 10
A23: 其他流动负债 | B23: 40
A24: 在产品 | B24: 11
A25: 流动负债合计 | B25: 41 | C25: 575000
A26: 库存商品 | B26: 12
A27: 周转材料 | B27: 13
A28: 长期借款 | B28: 42 | C28: 380000 | D28: 380000
A29: 其他流动资产 | B29: 14 | C29: 42000 | D29: 35000
A30: 长期应付款 | B30: 43
A31: 流动资产合计 | B31: 15 | C31: 1307000
A32: 递延收益 | B32: 44 | C32: 48000 | D32: 50000
A33: 其他非流动负债 | B33: 45
A34: 长期债券投资 | B34: 16
A35: 非流动负债合计 | B35: 46 | C35: 428000
A36: 长期股权投资 | B36: 17
A37: 负债合计 | B37: 47 | C37: 1003000
A38: 固定资产原价 | B38: 18 | C38: 865000 | D38: 780000
A39: 减：累计折旧 | B39: 19 | C39: 238000 | D39: 210000
A40: 固定资产账面价值 | B40: 20 | C40: 627000
...

Sheet 现金流量表-2025Q1
A1: 现金流量表
A2: 编制单位：上海云棱智能科技有限公司 | B2: 2025年第1季度 | D2: 单位：元
A3: 项目 | B3: 行次 | C3: 本期金额 | D3: 本年累计金额
A4: 销售产成品、商品、提供劳务收到的现金 | B4: 1 | C4: 870000 | D4: 870000
A5: 收到其他与经营活动有关的现金 | B5: 2 | C5: 70000 | D5: 70000
A6: 购买原材料、商品、接受劳务支付的现金 | B6: 3 | C6: 190000 | D6: 190000
A7: 支付的职工薪酬 | B7: 4 | C7: 330000 | D7: 330000
A8: 支付的税费 | B8: 5 | C8: 18000 | D8: 18000
A9: 支付其他与经营活动有关的现金 | B9: 6 | C9: 222000 | D9: 222000
A10: 经营活动产生的现金流量净额 | B10: 7 | C10: 180000 | D10: 180000
A11: 收回短期投资、长期债券投资和长期股权投资收到的现金 | B11: 8
A12: 取得投资收益收到的现金 | B12: 9
A13: 处置固定资产、无形资产和其他非流动资产收回的现金净额 | B13: 10
A14: 短期投资、长期债券投资和长期股权投资支付的现金 | B14: 11
A15: 购建固定资产、无形资产和其他非流动资产支付的现金 | B15: 12 | C15: 85000 | D15: 85000
A16: 投资活动产生的现金流量净额 | B16: 13 | C16: -85000 | D16: -85000
A17: 取得借款收到的现金 | B17: 14
A18: 吸收投资者投资收到的现金 | B18: 15 | C18: 250000 | D18: 250000
A19: 偿还借款本金支付的现金 | B19: 16
A20: 偿还借款利息支付的现金 | B20: 17
A21: 分配利润支付的现金 | B21: 18
A22: 筹资活动产生的现金流量净额 | B22: 19 | C22: 250000 | D22: 250000
A23: 四、现金净增加额 | B23: 20 | C23: 345000 | D23: 345000
A24: 加：期初现金余额 | B24: 21 | C24: 450000 | D24: 450000
A25: 期末现金余额 | B25: 22 | C25: 795000 | D25: 795000

Sheet 利润表-2025Q2
A1: 利润表
A2: 编制单位：上海云棱智能科技有限公司 | B2: 2025年第2季度 | D2: 单位：元
A3: 项目 | B3: 行次 | C3: 本年累计金额 | D3: 本期金额
A4: 一、营业收入 | B4: 1 | C4: 2210000 | D4: 1230000
A5: 减：营业成本 | B5: 2 | C5: 495000 | D5: 275000
A6: 税金及附加 | B6: 3 | C6: 9500 | D6: 5300
A7: 其中：消费税 | B7: 4
A8: 营业税 | B8: 5
A9: 城市维护建设税 | B9: 6
A10: 资源税 | B10: 7
A11: 土地增值税 | B11: 8
A12: 城镇土地使用税、房产税、车船税、印花税 | B12: 9
A13: 教育费附加、矿产资源补偿税、排污费 | B13: 10
A14: 销售费用 | B14: 11 | C14: 283000 | D14: 158000
A15: 其中：商品维修费 | B15: 12
A16: 广告费和业务宣传费 | B16: 13 | C16: 155650 | D16: 86900
A17: 管理费用 | B17: 14 | C17: 655000 | D17: 345000
A18: 其中：开办费 | B18: 15
A19: 业务招待费 | B19: 16 | C19: 7860 | D19: 4140
A20: 研发费用 | B20: 17 | C20: 395000 | D20: 215000
A21: 财务费用 | B21: 18 | C21: 7800 | D21: 4200
A22: 其中：利息费用(收入以"-"号填列) | B22: 19 | C22: 7800 | D22: 4200
A23: 加：投资收益(损失以"-"号填列) | B23: 20
A24: 二、营业利润 | B24: 21 | C24: 364700 | D24: 227500
A25: 加：营业外收入 | B25: 22 | C25: 20000 | D25: 8000
A26: 其中：政府补助 | B26: 23
A27: 减：营业外支出 | B27: 24
A28: 其中：坏账损失 | B28: 25
A29: 无法收回的长期债券投资损失 | B29: 26
A30: 无法收回的长期股权投资损失 | B30: 27
A31: 自然灾害等不可抗力因素造成的损失 | B31: 28
A32: 税收滞纳金 | B32: 29
A33: 三、利润总额(亏损总额以"-"号填列) | B33: 30 | C33: 384700 | D33: 235500
A34: 减：所得税费用 | B34: 31 | C34: 57705 | D34: 35325
A35: 四、净利润 | B35: 32 | C35: 326995 | D35: 200175

Sheet 资产负债表-2025Q2
A1: 资产负债表
A2: 编制单位：上海云棱智能科技有限公司 | B2: 45838 | D2: 单位：元
A3: 项目 | B3: 行次 | C3: 期末余额 | D3: 年初余额
A4: 货币资金 | B4: 1 | C4: 916000 | D4: 450000
A5: 短期借款 | B5: 31
A6: 短期投资 | B6: 2
A7: 应付票据 | B7: 32
A8: 应收票据 | B8: 3
A9: 应付账款 | B9: 33 | C9: 245000 | D9: 180000
A10: 应收账款 | B10: 4 | C10: 390000 | D10: 260000
A11: 预收账款 | B11: 34 | C11: 135000 | D11: 90000
A12: 预付账款 | B12: 5 | C12: 95000 | D12: 80000
A13: 应付职工薪酬 | B13: 35 | C13: 162000 | D13: 125000
A14: 应收股利 | B14: 6
A15: 应交税费 | B15: 36 | C15: 56000 | D15: 35000
A16: 应收利息 | B16: 7
A17: 应付利息 | B17: 37
A18: 其他应收款 | B18: 8 | C18: 52000 | D18: 45000
A19: 应付利润 | B19: 38
A20: 存货 | B20: 9
A21: 其他应付款 | B21: 39 | C21: 82000 | D21: 70000
A22: 其中：原材料 | B22: 10
A23: 其他流动负债 | B23: 40
A24: 在产品 | B24: 11
A25: 流动负债合计 | B25: 41 | C25: 680000
A26: 库存商品 | B26: 12
A27: 周转材料 | B27: 13
A28: 长期借款 | B28: 42 | C28: 380000 | D28: 380000
A29: 其他流动资产 | B29: 14 | C29: 45000 | D29: 35000
A30: 长期应付款 | B30: 43
A31: 流动资产合计 | B31: 15 | C31: 1498000
A32: 递延收益 | B32: 44 | C32: 45000 | D32: 50000
A33: 其他非流动负债 | B33: 45
A34: 长期债券投资 | B34: 16
A35: 非流动负债合计 | B35: 46 | C35: 425000
A36: 长期股权投资 | B36: 17
A37: 负债合计 | B37: 47 | C37: 1105000
A38: 固定资产原价 | B38: 18 | C38: 960000 | D38: 780000
A39: 减：累计折旧 | B39: 19 | C39: 270000 | D39: 210000
A40: 固定资产账面价值 | B40: 20 | C40: 690000
...

Sheet 现金流量表-2025Q2
A1: 现金流量表
A2: 编制单位：上海云棱智能科技有限公司 | B2: 2025年第2季度 | D2: 单位：元
A3: 项目 | B3: 行次 | C3: 本期金额 | D3: 本年累计金额
A4: 销售产成品、商品、提供劳务收到的现金 | B4: 1 | C4: 1185000 | D4: 2055000
A5: 收到其他与经营活动有关的现金 | B5: 2 | C5: 65000 | D5: 135000
A6: 购买原材料、商品、接受劳务支付的现金 | B6: 3 | C6: 235000 | D6: 425000
A7: 支付的职工薪酬 | B7: 4 | C7: 386000 | D7: 716000
A8: 支付的税费 | B8: 5 | C8: 24000 | D8: 42000
A9: 支付其他与经营活动有关的现金 | B9: 6 | C9: 383000 | D9: 605000
A10: 经营活动产生的现金流量净额 | B10: 7 | C10: 222000 | D10: 402000
A11: 收回短期投资、长期债券投资和长期股权投资收到的现金 | B11: 8
A12: 取得投资收益收到的现金 | B12: 9
A13: 处置固定资产、无形资产和其他非流动资产收回的现金净额 | B13: 10
A14: 短期投资、长期债券投资和长期股权投资支付的现金 | B14: 11
A15: 购建固定资产、无形资产和其他非流动资产支付的现金 | B15: 12 | C15: 95000 | D15: 180000
A16: 投资活动产生的现金流量净额 | B16: 13 | C16: -95000 | D16: -180000
A17: 取得借款收到的现金 | B17: 14
A18: 吸收投资者投资收到的现金 | B18: 15 | D18: 250000
A19: 偿还借款本金支付的现金 | B19: 16
A20: 偿还借款利息支付的现金 | B20: 17 | C20: 6000 | D20: 6000
A21: 分配利润支付的现金 | B21: 18
A22: 筹资活动产生的现金流量净额 | B22: 19 | C22: -6000 | D22: 244000
A23: 四、现金净增加额 | B23: 20 | C23: 121000 | D23: 466000
A24: 加：期初现金余额 | B24: 21 | C24: 795000 | D24: 450000
A25: 期末现金余额 | B25: 22 | C25: 916000 | D25: 916000

Sheet 利润表-2025Q3
A1: 利润表
A2: 编制单位：上海云棱智能科技有限公司 | B2: 2025年第3季度 | D2: 单位：元
A3: 项目 | B3: 行次 | C3: 本年累计金额 | D3: 本期金额
A4: 一、营业收入 | B4: 1 | C4: 3720000 | D4: 1510000
A5: 减：营业成本 | B5: 2 | C5: 851000 | D5: 356000
A6: 税金及附加 | B6: 3 | C6: 16100 | D6: 6600
A7: 其中：消费税 | B7: 4
A8: 营业税 | B8: 5
A9: 城市维护建设税 | B9: 6
A10: 资源税 | B10: 7
A11: 土地增值税 | B11: 8
A12: 城镇土地使用税、房产税、车船税、印花税 | B12: 9
A13: 教育费附加、矿产资源补偿税、排污费 | B13: 10
A14: 销售费用 | B14: 11 | C14: 471000 | D14: 188000
A15: 其中：商品维修费 | B15: 12
A16: 广告费和业务宣传费 | B16: 13 | C16: 259050 | D16: 103400
A17: 管理费用 | B17: 14 | C17: 1037000 | D17: 382000
A18: 其中：开办费 | B18: 15
A19: 业务招待费 | B19: 16 | C19: 12444 | D19: 4584
A20: 研发费用 | B20: 17 | C20: 640000 | D20: 245000
A21: 财务费用 | B21: 18 | C21: 12900 | D21: 5100
A22: 其中：利息费用(收入以"-"号填列) | B22: 19 | C22: 12900 | D22: 5100
A23: 加：投资收益(损失以"-"号填列) | B23: 20
A24: 二、营业利润 | B24: 21 | C24: 692000 | D24: 327300
A25: 加：营业外收入 | B25: 22 | C25: 29000 | D25: 9000
A26: 其中：政府补助 | B26: 23
A27: 减：营业外支出 | B27: 24
A28: 其中：坏账损失 | B28: 25
A29: 无法收回的长期债券投资损失 | B29: 26
A30: 无法收回的长期股权投资损失 | B30: 27
A31: 自然灾害等不可抗力因素造成的损失 | B31: 28
A32: 税收滞纳金 | B32: 29
A33: 三、利润总额(亏损总额以"-"号填列) | B33: 30 | C33: 721000 | D33: 336300
A34: 减：所得税费用 | B34: 31 | C34: 108150 | D34: 50445
A35: 四、净利润 | B35: 32 | C35: 612850 | D35: 285855

Sheet 资产负债表-2025Q3
A1: 资产负债表
A2: 编制单位：上海云棱智能科技有限公司 | B2: 45930 | D2: 单位：元
A3: 项目 | B3: 行次 | C3: 期末余额 | D3: 年初余额
A4: 货币资金 | B4: 1 | C4: 1111000 | D4: 450000
A5: 短期借款 | B5: 31
A6: 短期投资 | B6: 2
A7: 应付票据 | B7: 32
A8: 应收票据 | B8: 3
A9: 应付账款 | B9: 33 | C9: 280000 | D9: 180000
A10: 应收账款 | B10: 4 | C10: 455000 | D10: 260000
A11: 预收账款 | B11: 34 | C11: 160000 | D11: 90000
A12: 预付账款 | B12: 5 | C12: 102000 | D12: 80000
A13: 应付职工薪酬 | B13: 35 | C13: 188000 | D13: 125000
A14: 应收股利 | B14: 6
A15: 应交税费 | B15: 36 | C15: 72000 | D15: 35000
A16: 应收利息 | B16: 7
A17: 应付利息 | B17: 37
A18: 其他应收款 | B18: 8 | C18: 54000 | D18: 45000
A19: 应付利润 | B19: 38
A20: 存货 | B20: 9
A21: 其他应付款 | B21: 39 | C21: 90000 | D21: 70000
A22: 其中：原材料 | B22: 10
A23: 其他流动负债 | B23: 40
A24: 在产品 | B24: 11
A25: 流动负债合计 | B25: 41 | C25: 790000
A26: 库存商品 | B26: 12
A27: 周转材料 | B27: 13
A28: 长期借款 | B28: 42 | C28: 380000 | D28: 380000
A29: 其他流动资产 | B29: 14 | C29: 50000 | D29: 35000
A30: 长期应付款 | B30: 43
A31: 流动资产合计 | B31: 15 | C31: 1772000
A32: 递延收益 | B32: 44 | C32: 42000 | D32: 50000
A33: 其他非流动负债 | B33: 45
A34: 长期债券投资 | B34: 16
A35: 非流动负债合计 | B35: 46 | C35: 422000
A36: 长期股权投资 | B36: 17
A37: 负债合计 | B37: 47 | C37: 1212000
A38: 固定资产原价 | B38: 18 | C38: 1080000 | D38: 780000
A39: 减：累计折旧 | B39: 19 | C39: 310000 | D39: 210000
A40: 固定资产账面价值 | B40: 20 | C40: 770000
...

Sheet 现金流量表-2025Q3
A1: 现金流量表
A2: 编制单位：上海云棱智能科技有限公司 | B2: 2025年第3季度 | D2: 单位：元
A3: 项目 | B3: 行次 | C3: 本期金额 | D3: 本年累计金额
A4: 销售产成品、商品、提供劳务收到的现金 | B4: 1 | C4: 1485000 | D4: 3540000
A5: 收到其他与经营活动有关的现金 | B5: 2 | C5: 58000 | D5: 193000
A6: 购买原材料、商品、接受劳务支付的现金 | B6: 3 | C6: 302000 | D6: 727000
A7: 支付的职工薪酬 | B7: 4 | C7: 452000 | D7: 1168000
A8: 支付的税费 | B8: 5 | C8: 37000 | D8: 79000
A9: 支付其他与经营活动有关的现金 | B9: 6 | C9: 432000 | D9: 1037000
A10: 经营活动产生的现金流量净额 | B10: 7 | C10: 320000 | D10: 722000
A11: 收回短期投资、长期债券投资和长期股权投资收到的现金 | B11: 8
A12: 取得投资收益收到的现金 | B12: 9
A13: 处置固定资产、无形资产和其他非流动资产收回的现金净额 | B13: 10
A14: 短期投资、长期债券投资和长期股权投资支付的现金 | B14: 11
A15: 购建固定资产、无形资产和其他非流动资产支付的现金 | B15: 12 | C15: 120000 | D15: 300000
A16: 投资活动产生的现金流量净额 | B16: 13 | C16: -120000 | D16: -300000
A17: 取得借款收到的现金 | B17: 14
A18: 吸收投资者投资收到的现金 | B18: 15 | D18: 250000
A19: 偿还借款本金支付的现金 | B19: 16
A20: 偿还借款利息支付的现金 | B20: 17 | C20: 5000 | D20: 11000
A21: 分配利润支付的现金 | B21: 18
A22: 筹资活动产生的现金流量净额 | B22: 19 | C22: -5000 | D22: 239000
A23: 四、现金净增加额 | B23: 20 | C23: 195000 | D23: 661000
A24: 加：期初现金余额 | B24: 21 | C24: 916000 | D24: 450000
A25: 期末现金余额 | B25: 22 | C25: 1111000 | D25: 1111000

Sheet 利润表-2025Q4
A1: 利润表
A2: 编制单位：上海云棱智能科技有限公司 | B2: 2025年第4季度 | D2: 单位：元
A3: 项目 | B3: 行次 | C3: 本年累计金额 | D3: 本期金额
A4: 一、营业收入 | B4: 1 | C4: 5500000 | D4: 1780000
A5: 减：营业成本 | B5: 2 | C5: 1283000 | D5: 432000
A6: 税金及附加 | B6: 3 | C6: 23600 | D6: 7500
A7: 其中：消费税 | B7: 4
A8: 营业税 | B8: 5
A9: 城市维护建设税 | B9: 6
A10: 资源税 | B10: 7
A11: 土地增值税 | B11: 8
A12: 城镇土地使用税、房产税、车船税、印花税 | B12: 9
A13: 教育费附加、矿产资源补偿税、排污费 | B13: 10
A14: 销售费用 | B14: 11 | C14: 697000 | D14: 226000
A15: 其中：商品维修费 | B15: 12
A16: 广告费和业务宣传费 | B16: 13 | C16: 383350 | D16: 124300
A17: 管理费用 | B17: 14 | C17: 1447000 | D17: 410000
A18: 其中：开办费 | B18: 15
A19: 业务招待费 | B19: 16 | C19: 17364 | D19: 4920
A20: 研发费用 | B20: 17 | C20: 915000 | D20: 275000
A21: 财务费用 | B21: 18 | C21: 19300 | D21: 6400
A22: 其中：利息费用(收入以"-"号填列) | B22: 19 | C22: 19300 | D22: 6400
A23: 加：投资收益(损失以"-"号填列) | B23: 20
A24: 二、营业利润 | B24: 21 | C24: 1115100 | D24: 423100
A25: 加：营业外收入 | B25: 22 | C25: 44000 | D25: 15000
A26: 其中：政府补助 | B26: 23
A27: 减：营业外支出 | B27: 24
A28: 其中：坏账损失 | B28: 25
A29: 无法收回的长期债券投资损失 | B29: 26
A30: 无法收回的长期股权投资损失 | B30: 27
A31: 自然灾害等不可抗力因素造成的损失 | B31: 28
A32: 税收滞纳金 | B32: 29
A33: 三、利润总额(亏损总额以"-"号填列) | B33: 30 | C33: 1159100 | D33: 438100
A34: 减：所得税费用 | B34: 31 | C34: 173865 | D34: 65715
A35: 四、净利润 | B35: 32 | C35: 985235 | D35: 372385

Sheet 资产负债表-2025Q4
A1: 资产负债表
A2: 编制单位：上海云棱智能科技有限公司 | B2: 46022 | D2: 单位：元
A3: 项目 | B3: 行次 | C3: 期末余额 | D3: 年初余额
A4: 货币资金 | B4: 1 | C4: 1339000 | D4: 450000
A5: 短期借款 | B5: 31
A6: 短期投资 | B6: 2
A7: 应付票据 | B7: 32
A8: 应收票据 | B8: 3
A9: 应付账款 | B9: 33 | C9: 310000 | D9: 180000
A10: 应收账款 | B10: 4 | C10: 510000 | D10: 260000
A11: 预收账款 | B11: 34 | C11: 185000 | D11: 90000
A12: 预付账款 | B12: 5 | C12: 110000 | D12: 80000
A13: 应付职工薪酬 | B13: 35 | C13: 205000 | D13: 125000
A14: 应收股利 | B14: 6
A15: 应交税费 | B15: 36 | C15: 92000 | D15: 35000
A16: 应收利息 | B16: 7
A17: 应付利息 | B17: 37
A18: 其他应收款 | B18: 8 | C18: 56000 | D18: 45000
A19: 应付利润 | B19: 38
A20: 存货 | B20: 9
A21: 其他应付款 | B21: 39 | C21: 96000 | D21: 70000
A22: 其中：原材料 | B22: 10
A23: 其他流动负债 | B23: 40
A24: 在产品 | B24: 11
A25: 流动负债合计 | B25: 41 | C25: 888000
A26: 库存商品 | B26: 12
A27: 周转材料 | B27: 13
A28: 长期借款 | B28: 42 | C28: 380000 | D28: 380000
A29: 其他流动资产 | B29: 14 | C29: 55000 | D29: 35000
A30: 长期应付款 | B30: 43
A31: 流动资产合计 | B31: 15 | C31: 2070000
A32: 递延收益 | B32: 44 | C32: 40000 | D32: 50000
A33: 其他非流动负债 | B33: 45
A34: 长期债券投资 | B34: 16
A35: 非流动负债合计 | B35: 46 | C35: 420000
A36: 长期股权投资 | B36: 17
A37: 负债合计 | B37: 47 | C37: 1308000
A38: 固定资产原价 | B38: 18 | C38: 1230000 | D38: 780000
A39: 减：累计折旧 | B39: 19 | C39: 360000 | D39: 210000
A40: 固定资产账面价值 | B40: 20 | C40: 870000
...

Sheet 现金流量表-2025Q4
A1: 现金流量表
A2: 编制单位：上海云棱智能科技有限公司 | B2: 2025年第4季度 | D2: 单位：元
A3: 项目 | B3: 行次 | C3: 本期金额 | D3: 本年累计金额
A4: 销售产成品、商品、提供劳务收到的现金 | B4: 1 | C4: 1755000 | D4: 5295000
A5: 收到其他与经营活动有关的现金 | B5: 2 | C5: 83000 | D5: 276000
A6: 购买原材料、商品、接受劳务支付的现金 | B6: 3 | C6: 375000 | D6: 1102000
A7: 支付的职工薪酬 | B7: 4 | C7: 506000 | D7: 1674000
A8: 支付的税费 | B8: 5 | C8: 52000 | D8: 131000
A9: 支付其他与经营活动有关的现金 | B9: 6 | C9: 522000 | D9: 1559000
A10: 经营活动产生的现金流量净额 | B10: 7 | C10: 383000 | D10: 1105000
A11: 收回短期投资、长期债券投资和长期股权投资收到的现金 | B11: 8
A12: 取得投资收益收到的现金 | B12: 9
A13: 处置固定资产、无形资产和其他非流动资产收回的现金净额 | B13: 10
A14: 短期投资、长期债券投资和长期股权投资支付的现金 | B14: 11
A15: 购建固定资产、无形资产和其他非流动资产支付的现金 | B15: 12 | C15: 150000 | D15: 450000
A16: 投资活动产生的现金流量净额 | B16: 13 | C16: -150000 | D16: -450000
A17: 取得借款收到的现金 | B17: 14
A18: 吸收投资者投资收到的现金 | B18: 15 | D18: 250000
A19: 偿还借款本金支付的现金 | B19: 16
A20: 偿还借款利息支付的现金 | B20: 17 | C20: 5000 | D20: 16000
A21: 分配利润支付的现金 | B21: 18
A22: 筹资活动产生的现金流量净额 | B22: 19 | C22: -5000 | D22: 234000
A23: 四、现金净增加额 | B23: 20 | C23: 228000 | D23: 889000
A24: 加：期初现金余额 | B24: 21 | C24: 1111000 | D24: 450000
A25: 期末现金余额 | B25: 22 | C25: 1339000 | D25: 1339000
